Workbook

Sheet 参数
A1: 参数 | B1: 值 | C1: 说明
A2: USD/CNY 汇率 | B2: 7.1 | C2: 修改此格，对照表里的美元进价/售价自动更新
A3: 加价率 | B3: 0.3 | C3: 贸易商加价（买100卖130 = 0.30）
A5: 价格来源说明
A6: MikroTik = 官网 Suggested price (MSRP)。标 ✅ 为 2026-09 官网实测；标 * 为仓库 Excel 抓取值，建议核实。
A7: SmartByte = 价格表 2026.09.01–2026.12.30 未税 RMB 进价（for Simon）。
A9: MikroTik 出口地数据 = UN Comtrade 2024（见 'MikroTik出口地(Comtrade2024)' sheet）；MikroTik 营收 2023/2024/2025 = €401.6M / €326.7M / €344.6M（Lursoft）。

Sheet 替代对照表
A1: MikroTik 型号 | B1: MikroTik 端口/要点 | C1: MSRP USD | D1: 价格来源 | E1: 最接近的 SmartByte 型号 | F1: SmartByte 端口/要点 | G1: 进价 RMB | H1: ≈进价 USD | I1: 建议售价 USD | J1: 售价/MSRP | K1: 你赢在 | L1: 你输在 / 注意 | M1: 匹配度
A2: CSS326-24G-2S+RM | B2: 24G+2×SFP+；SwOS only；98DX3216；无CLI/SSH/LLDP/Trap；SNMP只读；250 VLAN/32 ACL；-20~70°C | C2: 159 | D2: ✅ | E2: LT-S8328XG-4XS24GT-S | F2: 24G+4×SFP+(1/2.5/10G)；L2+；AC5 1.2GHz 512MB/512MB；Console；0~50°C；3年保修 | G2: 710 | H2: =IF(G2="","",ROUND(G2/参数!$B$2,0)) | I2: =IF(G2="","",ROUND(G2/参数!$B$2*(1+参数!$B$3),0)) | J2: =IF(OR(G2="",C2=""),"",ROUND(I2/C2,2)) | K2: 4×10G、Cisco风格CLI/SSH、SNMPv3+Trap、LLDP、MSTP+ERPS、QinQ、480 ACL、静态路由、MQTT | L2: 温度 0~50 vs -20~70 | M2: ★★★★★ 降维打击
A3: CRS326-24G-2S+RM | B3: 24G+2×SFP+；RouterOS/SwOS；98DX3236 ARM 2×800MHz；-40~60°C；有QinQ/MSTP/L3卸载/API | C3: 209 | D3: ✅ | E3: LT-S8328XG-4XS24GT-S | F3: 同上 | G3: 710 | H3: =IF(G3="","",ROUND(G3/参数!$B$2,0)) | I3: =IF(G3="","",ROUND(G3/参数!$B$2*(1+参数!$B$3),0)) | J3: =IF(OR(G3="",C3=""),"",ROUND(I3/C3,2)) | K3: 4×10G、ERPS <20ms、MQTT、3年保修、OEM No MOQ | L3: RouterOS生态(API/脚本/Winbox)、-40°C；别拿QinQ/MSTP/L3当差异 | M3: ★★★★ 补空白
A4: CRS326-24G-2S+IN (桌面) | B4: 24G+2×SFP+ 桌面款 | C4: 199 | D4: * | E4: LT-S8328G-4GX24GT-S | F4: 24G+4×1G/2.5G SFP；L2+ | G4: 460 | H4: =IF(G4="","",ROUND(G4/参数!$B$2,0)) | I4: =IF(G4="","",ROUND(G4/参数!$B$2*(1+参数!$B$3),0)) | J4: =IF(OR(G4="",C4=""),"",ROUND(I4/C4,2)) | K4: 价格约为 MSRP 40% | L4: 上联只有 2.5G SFP | M4: ★★★
A5: CRS328-24P-4S+RM | B5: 24×PoE af/at 450W(3×150W)、30W/口、4×SFP+、500W PSU、-20~60°C、2风扇、无bt | C5: 489 | D5: ✅ | E5: LT-S8328XGP-4XS24GT-S | F5: 24×PoE af/at + 4×SFP+ 10G；280W；PoE看门狗/定时/优先级 | G5: 1010 | H5: =IF(G5="","",ROUND(G5/参数!$B$2,0)) | I5: =IF(G5="","",ROUND(G5/参数!$B$2*(1+参数!$B$3),0)) | J5: =IF(OR(G5="",C5=""),"",ROUND(I5/C5,2)) | K5: 价格、PoE 管理(PD Alive/定时/告警阈值)、ERPS、MQTT | L5: PoE预算 280 vs 450W；440W 版只有 2.5G 上联 (LT-S8328GP-4GX24GT RMB 1200)；需向工厂确认 24P+4×10G+440W 组合 | M5: ★★★★
A6: CRS328-24P-4S+RM (工业替代) | B6: 同上 | C6: 489 | D6: ✅ | E6: LT-IS6328XGP-4XS24GT / -4BT | F6: 24×PoE + 4×SFP+ 10G；工业 DIN、双DC、-40~75°C、5年保修；-4BT 带 4 个 90W 口 | G6: 2200 | H6: =IF(G6="","",ROUND(G6/参数!$B$2,0)) | I6: =IF(G6="","",ROUND(G6/参数!$B$2*(1+参数!$B$3),0)) | J6: =IF(OR(G6="",C6=""),"",ROUND(I6/C6,2)) | K6: 宽温、PoE++、IEC 61000-4、5年保修 | L6: 比 MikroTik 贵；只在工业/户外场景推 | M6: ★★★ 场景型
A7: CRS354-48G-4S+2Q+RM | B7: 48G+4×SFP+ +2×QSFP+ 40G | C7: 599 | D7: * | E7: LT-S8352XG-4XS48GT | F7: 48G+4×SFP+ 10G；L2+ | G7: 1470 | H7: =IF(G7="","",ROUND(G7/参数!$B$2,0)) | I7: =IF(G7="","",ROUND(G7/参数!$B$2*(1+参数!$B$3),0)) | J7: =IF(OR(G7="",C7=""),"",ROUND(I7/C7,2)) | K7: 价格、ERPS、PoE 版可选 | L7: 没有 40G QSFP+ | M7: ★★★
A8: CRS354-48P-4S+2Q+RM | B8: 48×PoE af/at + 4×SFP+ + 2×QSFP+ | D8: * | E8: LT-S8352XGP-4XS48GT (440W) / -850W | F8: 48×PoE + 4×SFP+ 10G；440W 或 850W | G8: 1870 | H8: =IF(G8="","",ROUND(G8/参数!$B$2,0)) | I8: =IF(G8="","",ROUND(G8/参数!$B$2*(1+参数!$B$3),0)) | J8: =IF(OR(G8="",C8=""),"",ROUND(I8/C8,2)) | K8: 850W 选项、PoE 管理 | L8: 没有 40G；MSRP 待核实 | M8: ★★★
A9: CSS610-8G-2S+IN | B9: 8G+2×SFP+；SwOS Lite；88E6193X；64KB flash；-20~60°C | C9: 119 | D9: ✅ | E9: LT-S8310XG-2XS8GT | F9: 8G+2×SFP+ 10G；L2+ 全管理 | H9: =IF(G9="","",ROUND(G9/参数!$B$2,0)) | I9: =IF(G9="","",ROUND(G9/参数!$B$2*(1+参数!$B$3),0)) | J9: =IF(OR(G9="",C9=""),"",ROUND(I9/C9,2)) | K9: 全管理 vs 傻瓜 Web | L9: 商业 8 口 L2+ 暂停出货、价格待询；8 口档 MikroTik 价格很硬 | M9: ★★
A10: CSS610-8P-2S+IN | B10: 8×PoE + 2×SFP+；SwOS Lite | C10: 139 | D10: * | E10: LT-S8310GP-2GX8GT | F10: 8×PoE(120W) + 2×1G/2.5G SFP；L2+ | G10: 450 | H10: =IF(G10="","",ROUND(G10/参数!$B$2,0)) | I10: =IF(G10="","",ROUND(G10/参数!$B$2*(1+参数!$B$3),0)) | J10: =IF(OR(G10="",C10=""),"",ROUND(I10/C10,2)) | K10: 价格、PoE 管理、全管理 | L10: 上联 2.5G 非 10G；暂停出货中 | M10: ★★★
A11: CRS106-1C-5S (Frank 6口) | B11: 1 Combo + 5×SFP；RouterOS；QCA8511 | C11: 89 | D11: * | E11: LT-IS6306G-2GX4GT | F11: 4G + 2×SFP；工业 DIN、IP40、双DC 12–58V、-40~75°C、5年 | G11: 660 | H11: =IF(G11="","",ROUND(G11/参数!$B$2,0)) | I11: =IF(G11="","",ROUND(G11/参数!$B$2*(1+参数!$B$3),0)) | J11: =IF(OR(G11="",C11=""),"",ROUND(I11/C11,2)) | K11: 出厂即加固(省他自己的外壳)、ERPS、双DC、4KV浪涌 | L11: 4电口 vs 5光口，形态不同；进价≈他现在含外壳成本 | M11: ★★★★ Frank 直接对位
A12: CRS112-8G-4S-IN (Frank 12口) | B12: 8G + 4×SFP；RouterOS；QCA8511 | C12: 119 | D12: * | E12: LT-IS6312G-4GX8GT | F12: 8G + 4×1G/2.5G SFP；工业 | G12: 740 | H12: =IF(G12="","",ROUND(G12/参数!$B$2,0)) | I12: =IF(G12="","",ROUND(G12/参数!$B$2*(1+参数!$B$3),0)) | J12: =IF(OR(G12="",C12=""),"",ROUND(I12/C12,2)) | K12: 同上 + 2.5G SFP | L12: 加价后比他现在成本略高 | M12: ★★★★ Frank 直接对位
A13: CRS112-8G-4S-IN (10G 上联版) | B13: 同上 | C13: 119 | D13: * | E13: LT-IS6312XG-4XS8GT | F13: 8G + 4×SFP+ 10G；工业 | G13: 840 | H13: =IF(G13="","",ROUND(G13/参数!$B$2,0)) | I13: =IF(G13="","",ROUND(G13/参数!$B$2*(1+参数!$B$3),0)) | J13: =IF(OR(G13="",C13=""),"",ROUND(I13/C13,2)) | K13: 10G 上联、ERPS、工业 | L13: 贵 ~30% | M13: ★★★★
A14: CRS112-8P-4S-IN | B14: 8×PoE(被动/af/at) + 4×SFP；-20~60°C | C14: 199 | D14: * | E14: LT-IS6312GP-4GX8GT / -2BT | F14: 8×PoE + 4×SFP；工业；-2BT 带 2 个 90W 口 | G14: 820 | H14: =IF(G14="","",ROUND(G14/参数!$B$2,0)) | I14: =IF(G14="","",ROUND(G14/参数!$B$2*(1+参数!$B$3),0)) | J14: =IF(OR(G14="",C14=""),"",ROUND(I14/C14,2)) | K14: PoE++ 选项、工业、PoE 看门狗 | L14: — | M14: ★★★★
A15: CRS310-8G+2S+IN | B15: 8×2.5GbE + 2×SFP+ | C15: 149 | D15: * | E15: 无对等 | F15: 你没有 2.5G 电口产品 | H15: =IF(G15="","",ROUND(G15/参数!$B$2,0)) | I15: =IF(G15="","",ROUND(G15/参数!$B$2*(1+参数!$B$3),0)) | J15: =IF(OR(G15="",C15=""),"",ROUND(I15/C15,2)) | K15: — | L15: 放弃 | M15: —
A16: CRS310-1G-5S-4S+IN | B16: 1G + 5×SFP + 4×SFP+；98DX226S | C16: 195 | D16: * | E16: LT-IS6316XG-4XS4GX8GT | F16: 8G + 4×SFP + 4×SFP+；工业 | G16: 1400 | H16: =IF(G16="","",ROUND(G16/参数!$B$2,0)) | I16: =IF(G16="","",ROUND(G16/参数!$B$2*(1+参数!$B$3),0)) | J16: =IF(OR(G16="",C16=""),"",ROUND(I16/C16,2)) | K16: 工业、ERPS、电口多 | L16: 贵、形态不同 | M16: ★★
A17: CRS318-16P-2S+RM / netPower 16P | B17: 16×PoE + 2×SFP+ (netPower 是户外反向PoE) | C17: 329 | D17: * | E17: LT-IS6318XGP-2XS16GT | F17: 16×PoE + 2×SFP+ 10G；工业 | G17: 1660 | H17: =IF(G17="","",ROUND(G17/参数!$B$2,0)) | I17: =IF(G17="","",ROUND(G17/参数!$B$2*(1+参数!$B$3),0)) | J17: =IF(OR(G17="",C17=""),"",ROUND(I17/C17,2)) | K17: 工业、PoE 管理 | L17: 贵；netPower 是不同物种 | M17: ★★
A18: CRS320-8P-8B-4S+RM | B18: 8×af/at + 8×bt + 4×SFP+ | C18: 299 | D18: * | E18: LT-IS6320GP-4GX16GT-D-4BT | F18: 16×PoE(4 个 bt) + 4×SFP + DI/DO/RS485；工业 | G18: 1960 | H18: =IF(G18="","",ROUND(G18/参数!$B$2,0)) | I18: =IF(G18="","",ROUND(G18/参数!$B$2*(1+参数!$B$3),0)) | J18: =IF(OR(G18="",C18=""),"",ROUND(I18/C18,2)) | K18: DI/DO/RS485、工业、ERPS | L18: 只有 4 个 bt 口；MSRP 抓取值不一致(299/489) | M18: ★★
A19: CRS328-4C-20S-4S+RM | B19: 4 Combo + 20×SFP + 4×SFP+ | C19: 299 | D19: * | E19: LT-IS6328XG-4XS16GX8GC-D | F19: 16×SFP + 8 Combo + 4×SFP+ + DI/DO；工业 | G19: 2650 | H19: =IF(G19="","",ROUND(G19/参数!$B$2,0)) | I19: =IF(G19="","",ROUND(G19/参数!$B$2*(1+参数!$B$3),0)) | J19: =IF(OR(G19="",C19=""),"",ROUND(I19/C19,2)) | K19: 工业 | L19: MikroTik 便宜一半 —— 放弃 | M19: ✗
A20: CRS305 / CRS309 / CRS317 / CRS326-24S+2Q+ / CRS504 / CRS510 | B20: 全 SFP+ / 25G / 100G | D20: * | E20: 无对等 | F20: — | H20: =IF(G20="","",ROUND(G20/参数!$B$2,0)) | I20: =IF(G20="","",ROUND(G20/参数!$B$2*(1+参数!$B$3),0)) | J20: =IF(OR(G20="",C20=""),"",ROUND(I20/C20,2)) | K20: — | L20: 放弃：MikroTik 在全光/高速档价格无敌 | M20: ✗

Sheet 竞品全景
A1: 品牌 | B1: 代表型号 | C1: ≈价格 USD | D1: 价格来源 | E1: 定位 | F1: 强项 | G1: 弱项 | H1: ERPS | I1: OEM | J1: 工业线 | K1: 保修 | L1: 对你的威胁 | M1: 你的打法
A2: MikroTik | B2: CSS326-24G-2S+RM | C2: 159 | D2: 官网 ✅ | E2: 傻瓜 Web 24 口 | F2: 价格、品牌、-20~70°C | G2: 无 CLI/SSH/LLDP/Trap，SNMP 只读，250 VLAN/32 ACL | H2: 否 | I2: 否 | J2: 否 | K2: 1 年 | L2: 低 | M2: 全面碾压
A3: MikroTik | B3: CRS326-24G-2S+RM | C3: 209 | D3: 官网 ✅ | E3: RouterOS 24 口 | F3: RouterOS 生态、API/REST/脚本、QinQ/MSTP/L3 卸载、-40~60°C | G3: 无 ERPS、无 PoE-out、2×SFP+、1 年保修 | H3: 否 | I3: 否 | J3: 否 | K3: 1 年 | L3: 中 | M3: 补空白：ERPS/PoE++/工业/OEM，价格低 1/3
A4: MikroTik | B4: CRS328-24P-4S+RM | C4: 489 | D4: 官网 ✅ | E4: 24 PoE af/at 450W | F4: 被动+标准 PoE、4×SFP+ | G4: 无 bt、-20~60°C、无 PoE 看门狗 | H4: 否 | I4: 否 | J4: 否 | K4: 1 年 | L4: 中 | M4: PoE 管理 + 工业款 + 价格
A5: MikroTik | B5: CRS354-48G-4S+2Q+RM | C5: 599 | D5: 官网 ✅ | E5: 48 口 + 40G | F5: 2×QSFP+ 40G | G5: QCA9531 650MHz/64MB，L3 极弱 | H5: 否 | I5: 否 | J5: 否 | K5: 1 年 | L5: 低 | M5: 无 40G 则用 LT-S8352XG
A6: MikroTik | B6: CRS418-8P-8G-2S+RM | C6: 449 | D6: 抓取 * | E6: 新方向：强 CPU 混合路由交换 | F6: 2.2GHz 四核、L3 卸载、可当路由器/CAPsMAN、双 AC | G6: 价格、-20°C | H6: 否 | I6: 否 | J6: 否 | K6: 1 年 | L6: 低 | M6: 不碰
A7: TP-Link Omada | B7: SG3428X | C7: 300 | D7: 零售 ≈259–367 | E7: 商业 L2+ 24G+4×SFP+ | F7: 有 ERPS、OAM、sFlow、DDM、CLI、Omada 云、终身有限保修、渠道广 | G7: 0~50°C、无工业线、不能 OEM、无 DI/DO | H7: 是 | I7: 否 | J7: 否 | K7: 终身有限 | L7: 高 | M7: 24 口只做敲门 SKU；用工业/PoE++/OEM 赚钱
A8: TP-Link Omada | B8: SG3428XMP | C8: 480 | D8: 零售 ≈ | E8: 24 PoE+ 384W + 4×SFP+ | F8: 同上 | G8: 同上 | H8: 是 | I8: 否 | J8: 否 | K8: 终身有限 | L8: 高 | M8: 同上
A9: Ubiquiti UniFi | B9: USW-24 | C9: 250 | D9: 零售 ≈219–295 | E9: L2 24G + 2×SFP 1G | F9: UI/控制器、品牌 | G9: 控制器依赖、无 SFP+、无 ERPS、无 QinQ | H9: 否 | I9: 否 | J9: 否 | K9: 1 年 | L9: 中 | M9: 对不想被控制器绑定的客户
A10: Ubiquiti UniFi | B10: USW-Pro-24 | C10: 399 | D10: store.ui.com | E10: L3 24G + 2×SFP+ | F10: UI/控制器、L3 | G10: 同上，价格高 | H10: 否 | I10: 否 | J10: 否 | K10: 1 年 | L10: 中 | M10: 价格 1/3 + CLI/SNMP/ERPS
A11: Teltonika Networks | B11: TSW212 | C11: 129 | D11: MSRP | E11: 工业 8G + 2×SFP 管理型 | F11: 价格、RMS 云、PROFINET/EtherNet-IP/MRP、7–57V、与 MikroTik 同渠道 | G11: 8K MAC/512KB 缓存、无 10G、无 ERPS、无 PoE++、无 QinQ/MSTP 级 L2+ | H11: 否(MRP) | I11: 否 | J11: 是 | K11: 2 年 | L11: 高 | M11: LT-IS6312XG：4×10G、ERPS、16K/12Mbit、PoE++、DI/DO、5 年
A12: PLANET | B12: IGS-5225-8P4S | C12: 790 | D12: 零售 757–828 | E12: 工业 8 PoE+ + 2 SFP + 2×2.5G SFP | F12: ERPS <10ms、MSTP、Modbus TCP、1588 透传、-40~75、TAA | G12: 价格 5–7×、交期 | H12: 是 | I12: 有限 | J12: 是 | K12: 5 年 | L12: 低 | M12: 'PLANET 的功能，MikroTik 的价格'
A13: ORing | B13: IGS-9084GP 类 | C13: 1000 | D13: ≈900–1200 | E13: 工业标杆 | F13: O-Ring <30ms、ERPS、EN50155、IP67、UL | G13: 价格 8–10× | H13: 是 | I13: 否 | J13: 是 | K13: 5 年 | L13: 低 | M13: 让出铁路/IP67/UL 项目
A14: 中国直供 | B14: Utepo/ONV/HRUI/UNIPOE | C14: - | D14: 低你 10–30% | E14: 低价管理/非管理 | F14: 价格、目录大 | G14: 软件弱、CLI 不规范、MIB 缺、文档差、无欧美支持 | H14: 部分 | I14: 是 | J14: 是 | K14: 1–3 年 | L14: 中 | M14: 不比裸价：Marvell+CLI+MIB+固件迭代+保修
A15: SmartByte (经你) | B15: LT-S8328XG-4XS24GT-S | C15: 130 | D15: 售价（进价 ≈100） | E15: 商业 L2+ 24G+4×SFP+ | F15: 4×10G、Cisco CLI、SNMPv3+Trap+私有 MIB、MQTT、ERPS、QinQ、480 ACL、双分区、OEM No MOQ、3 年 | G15: 0~50°C、无 API/云、品牌弱 | H15: 是 | I15: 是 | J15: 是（LT-IS 线） | K15: 3 年 / 工业 5 年 | L15: — | M15: —

Sheet Marvell品牌全景
A1: 品牌 | B1: 国家/地区 | C1: 类型 | D1: Marvell证据 | E1: 主战场 | F1: 关系 | G1: 切入点 | H1: 优先级
A2: MikroTik | B2: 拉脱维亚(欧盟) | C2: 品牌商 | D2: ✅ 官方文档列 98DX3236/3257/226S/2528/8332/4310 | E2: WISP/中小企业/工业 | F2: 主要对标 | G2: ERPS/PoE++/工业/贴牌补其空白 | H2: A
A3: Allied Telesis | B3: 日本/新西兰，美国总部 WA | C3: 品牌商 | D3: ✅ 内核补丁支持 98DX3236/3336/4251（作者 @alliedtelesis.co.nz） | E3: 欧美企业接入 L2/L3 | F3: 竞品+最大替换池 | G3: 老型号 EOL 替换、抢其渠道 | H3: A-替换
A4: Edgecore(Accton) | B4: 台湾 | C4: ODM/白牌 | D4: ✅ SAF51001I 规格书标注 8×GbE through 98DX3236 | E4: 数据中心/白牌 | F4: 旁证(台湾体系熟Marvell) | G4: 不做主攻 | H4: C
A5: PLANET Technology | B5: 台湾 | C5: 品牌商 | D5: ○ 混合(Realtek/Marvell) | E5: 工业/商业/电力/安防 | F5: 头号对标 | G5: 抄规格与文档、抢渠道 | H5: A-渠道
A6: Moxa | B6: 台湾 | C6: 品牌商 | D6: ○ | E6: 铁路/电力/海事 | F6: 高端锚 | G6: 只打备件/扩容/项目配套 | H6: C
A7: EtherWAN | B7: 台湾 | C7: 品牌商 | D7: ○ | E7: 工业/ITS/安防 | F7: 竞品 | G7: 抢 ITS 项目位置 | H7: B
A8: ORing | B8: 台湾 | C8: 品牌商 | D8: ○ | E8: 工业/ITS/铁路 | F8: 竞品 | G8: 让出铁路/IP67/UL 项目 | H8: C
A9: CTC Union | B9: 台湾 | C9: 品牌商(自有厂) | D9: ○ 官网明示 in-house R&D and factory | E9: 电信接入/工业, EN50155/IEC61850-3 | F9: 竞品 | G9: 关注 EOL 与运营商项目 | H9: B
A10: Lantech | B10: 台湾 | C10: 品牌商 | D10: ○ | E10: 工业 PoE/EN50155/E-mark | F10: 竞品,欧洲渠道密 | G10: 抢渠道 | H10: B
A11: Volktek | B11: 台湾 | C11: ODM+品牌 | D11: ● ODM 常用 Marvell 平台 | E11: 工业/企业 | F11: 第二供应源参考 | G11: 对标其工业线成本 | H11: B
A12: Korenix | B12: 台湾 | C12: 品牌商 | D12: ○ | E12: 工业无线+交换 | F12: 竞品(小) | G12: 观察 | H12: C
... A47: Datacom / Furukawa 拉美 | B47: 巴西 | C47: 品牌商 | D47: ○ | E47: 运营商/企业 | F47: 中长线 | G47: — | H47: C

Sheet A类客户速查
A1: # | B1: 公司 | C1: 国家 | D1: 主入口/联系方式 | E1: 现有交换机线 | F1: ⭐缺口 | G1: 首推 SKU | H1: 第一句话钩子 | I1: 最大风险 | J1: 优先级
A2: 1 | B2: Digital Data Communications (LevelOne/equip) | C2: 德国 Dortmund | D2: LinkedIn（Group CEO Amanda Chen）+ 官网；制造在台湾&中国 | E2: LevelOne PoE 交换机/媒转/AP，多为非管理与 web-smart | F2: 缺可管理 L2+ / L3 汇聚 / 工业宽温 | G2: LT-S8328XG + LT-IS6312XG | H2: 你们的 PoE 线最强，但停在 web-smart | I2: 他们自己也做 ODM 服务，可能视你为竞争 | J2: ⭐⭐⭐
A3: 2 | B3: 2direct GmbH (LogiLink) | C3: 德国 Schalksmühle | D3: 官网 kontakt；Langenstück 5, D-58579 | E3: LogiLink 网络线以配件/非管理为主 | F3: 缺可管理 L2+ 与工业线 | G3: 全系贴牌阶梯 | H3: 你们公开说做 OEM 项目 | I3: 价格敏感，需给阶梯价 | J3: ⭐⭐⭐
A4: 3 | B4: Nedis | C4: 荷兰 | D4: nedis.com/en-us/business/become-a-partner 表单 | E4: 8口千兆非管理(NSWH8P100BK)、8口PoE 150W(GS-1008P)、部分贴 Edimax | F4: 几乎只有非管理/SOHO | G4: 8/16/24口 PoE+ 贴牌 | H4: 你们贴牌覆盖所有品类，交换机只有非管理 | I4: 决策慢，需走品类经理 | J4: ⭐⭐
A5: 4 | B5: Distrelec (RS Group, 自有品牌 RND) | C5: 瑞士/欧洲 | D5: Supplier onboarding | E5: RND 以无源/仪器/元件为主 | F5: 缺有源网络（可管理/工业以太网） | G5: 工业线 + 可管理 | H5: RND 缺有源网络这一层 | I5: 供应商准入流程长 | J5: ⭐⭐
A6: 5 | B6: Conrad Electronic | C6: 德国 | D6: platform.conrad.de → Become a Seller（Mirakl 平台，已有650+卖家） | E6: 分销 + 自有品牌 | F6: 需德语内容/EAN/CE/WEEE/LUCID | G6: 自有品牌上架（最快出单） | H6: 4-8周即可上平台出单 | I6: 需德语产品数据与德国合规号 | J6: ⭐⭐
A7: 6 | B7: IC Intracom (Intellinet/Manhattan) | C7: 德国 Halver / 美国 FL | D7: sales@intellinetnetwork.eu；+49 2353 7007 0；WEEE DE40753042 / LUCID DE2489084505093 | E7: Intellinet 可管理偏少，多为非管理与 web-smart PoE | F7: 缺可管理 L2+ / PoE++ / 工业 | G7: 可管理 L2+ + 工业线 | H7: 你们亚洲有 QC、欧盟合规号齐全，沟通成本最低 | I7: 他们已有亚洲供应 | J7: ⭐⭐
A8: 7 | B8: Deltaco (DistIT → Aurdel) | C8: 瑞典 | D8: 官网 B2B | E8: 含 switches/转换器/光纤，偏北欧零售 SOHO | F8: 可管理 PoE 与工业线薄弱 | G8: 北欧 PoE+ / 工业线 | H8: 从台湾进口到自有品牌的这条路我们熟 | I8: 集团合并期，决策链变化 | J8: ⭐
A9: 8 | B9: StarTech.com | C9: 加拿大多伦多 | D9: 官网供应商入口（⚠️ 不要发冷邮件，CASL） | E9: IES61002POE / IES81000PoE(TAA) / IESC1G50UP / IES1G52UPDIN / IES5102 —— 全部非管理 | F9: 没有可管理工业交换机、无 PoE++、无环网 | G9: 可管理工业线 | H9: 你们的工业交换机全是非管理型 | I9: ⚠️ TAA SKU 不能碰（中国原产） | J9: ⭐
A10: 9 | B10: Intelbras | C10: 巴西 | D10: Amilcar Scheffer（网络方案与产品总监）/ Elton Thiesen（企业线经理） | E10: SG 5204 MR L2+、S3028G-PB Max(L3,380W)、SG 2404 PoE L2+ 等；与 H3C 合作本地化生产 | F10: 接入层低价位 / PoE++ / 工业宽温；SKD/CKD 机会 | G10: 接入层 + SKD/CKD 散件 | H10: H3C 覆盖核心，接入层与本地组装是空间 | I10: H3C 关系深；需葡语与 ANATEL 确认 | J10: ⭐
A11: 10 | B11: Antaira | C11: 美国(台系供应链) | D11: 其合作方：Switch SFP(UK)、Things Embedded | E11: 工业以太网为主 | F11: 同价位下规格与质保 | G11: 4×10G + PoE++ + ERPS | H11: 项目要更大规格时他们够不着 | I11: 主要是竞品；打其渠道 | J11: B
A12: 11 | B12: ComNet (ACRE) | C12: 美国 Danbury CT | D12: +1 203 796 5300；comnetcustomercare@acresecurity.com | E12: 光纤/铜缆/无线传输，有限终身质保，IEC61850-3 产品线 | F12: ITS/电力集成商渠道；非核心网段第二供应源 | G12: ITS 与电力项目配套 | H12: 打其下游集成商 | I12: 美国本土制造，本地保护 | J12: B
A13: 12 | B13: Teltonika Networks | C13: 立陶宛 | D13: 其各国分销商（如英国 Diamond 分销商 Millbeck） | E13: TSW202/TSW212（8×GE+2SFP，8K MAC/512KB，MSRP $129），开放 SDK 可自写固件 | F13: 无 10G 上行、无 PoE++、无 ERPS、只有 8 口 | G13: LT-IS6312XG 正面对冲 | H13: 8 口以上他们没有 | I13: 有 SDK + RMS 云，工程师粘性高 | J13: B

Sheet 反向信号名单
A1: 公司名 | B1: 国家 | C1: 城市 | D1: 网站 | E1: 类型 | F1: 信号（在卖什么品牌） | G1: 是否自有品牌 | H1: 切入点 | I1: 首推SmartByte型号 | J1: 入口/联系方式 | K1: 优先级 | L1: 状态 | M1: 来源 | N1: 首次触达日 | O1: 最后互动日 | P1: 下次跟进日 | Q1: 备注
A2: Spectra (oring.spectra.de) | B2: 德国 | D2: oring.spectra.de | E2: 分销+网店 | F2: ORing（全系，公开欧元价） | G2: 否 | H2: ORing价格高→1/3价做第二供应源 | I2: LT-IS6312XGP-4XS8GT | J2: 官网表单（德：不冷邮件）+LinkedIn | K2: ★★★ | L2: 未触达 | M2: 反向信号/2026-09 | Q2: 价格锚点最有用
A3: Fiber24 | B3: 德国 | D3: shop.fiber24.net | E3: 光通信/网络网店 | F3: PLANET IGS-5225 全系 | G3: 否 | H3: 同做网店，中性货接受度最高 | I3: LT-IS6312XG-4XS8GT | J3: 官网表单+LinkedIn | K3: ★★★ | L3: 未触达 | M3: 反向信号/2026-09
A4: IC Intracom (Intellinet/Manhattan) | B4: 德国 | C4: Halver | D4: icintracom.eu | E4: 自有品牌制造商 | F4: Intellinet/Manhattan | G4: 是 | H4: 亚洲有QC、欧盟合规号齐全，沟通成本最低 | I4: LT-S8328XG-4XS24GT-S | J4: sales@intellinetnetwork.eu / +49 2353 7007 0 | K4: ★★★ | L4: 未触达 | M4: 重点客户/2026-09 | Q4: WEEE DE40753042 / LUCID DE2489084505093
A5: Lantech Communications Europe GmbH | B5: 德国 | D5: — | E5: 台厂德国实体 | F5: Lantech（EN50155/铁路强） | G5: 是 | H5: 不打产品，铁路/EN50155让出 | I5: — | J5: — | K5: ✕ | L5: 未触达 | M5: 反向信号/2026-09
A6: Microsens | B6: 德国 | D6: — | E6: 工业网络品牌 | F6: Microsens | G6: 是 | H6: 高端锚，只做备件与项目配套 | I6: — | J6: — | K6: ✕ | L6: 未触达 | M6: 反向信号/2026-09
A7: Conrad / Reichelt / Distrelec | B7: 德国/瑞士 | D7: platform.conrad.de | E7: 大分销+自有品牌 | F7: RND 等 | G7: 部分 | H7: Conrad走Mirakl入驻；Distrelec供应商onboarding | I7: LT-S8328XGP-4XS24GT-S | J7: 各官网入驻入口 | K7: ★★★ | L7: 未触达 | M7: 重点客户/2026-09 | Q7: 最快出单路径
A8: shop4power.nl | B8: 荷兰 | D8: shop4power.nl | E8: 分销+自有品牌 | F8: PLANET + E-Link | G8: 是 | H8: 已做OEM/贴牌，最容易谈中性货 | I8: LT-S8328XGP-4XS24GT-S | J8: 官网表单+邮件 | K8: ★★★ | L8: 未触达 | M8: 反向信号/2026-09 | Q8: Benelux Planet Partner
A9: Nedis | B9: 荷兰 | C9: 's-Hertogenbosch | D9: nedis.com | E9: 自有品牌分销 | F9: Nedis（交换机仅非管理） | G9: 是 | H9: 补可管理/24口/PoE++ | I9: LT-S8328XGP-4XS24GT-S | J9: +31 73 599 1055 / become-a-partner表单 | K9: ★★ | L9: 未触达 | M9: 重点客户/2026-09 | Q9: Chaitanya Mhatre (Director Sales Asia)
A10: TME (Transfer Multisort Elektronik) | B10: 波兰 | D10: tme.eu | E10: 大分销 | F10: Moxa（EDS-405A €429） | G10: 否 | H10: 体量大流程长，先做1个型号试单 | I10: LT-IS6312XG-4XS8GT | J10: 官网B2B | K10: ★★ | L10: 未触达 | M10: 反向信号/2026-09
A11: Cyberbajt | B11: 波兰 | D11: cyberbajt.pl | E11: 集成/分销 | F11: Moxa 工业交换机 | G11: 否 | H11: 波兰T1，用LT-IS打价格 | I11: LT-IS6312XGP-4XS8GT | J11: 官网kontakt | K11: ★★★ | L11: 未触达 | M11: 反向信号/2026-09
A12: BCS | B12: 波兰/捷克 | D12: — | E12: CCTV自有品牌 | F12: BCS（工业PoE交换机） | G12: 是 | H12: ⭐OEM目标：安防品牌补工业线 | I12: LT-IS6312XGP-4XS8GT | J12: 官网 | K12: ★★★ | L12: 未触达 | M12: 反向信号/2026-09 | Q12: 待查具体联系人
A13: Proficomms | B13: 捷克 | D13: proficomms.cz | E13: 专业分销 | F13: ComNet/Microsens/AMG/PLANET/Cisco IE/TRENDnet | G13: 否 | H13: 已代理6个品牌，加第7个阻力小 | I13: LT-IS6320G-4GX16GT-D | J13: 官网kontakt | K13: ★★★ | L13: 未触达 | M13: 反向信号/2026-09
A14: SECOMP | B14: 捷克 | D14: secomp.cz | E14: 分销 | F14: TRENDnet TI-PG102 等 | G14: 否 | H14: 第二供应源 | I14: LT-IS6318GP-2GX16GT | J14: 官网 | K14: ★★ | L14: 未触达 | M14: 反向信号/2026-09
A15: TS Bohemia | B15: 捷克 | D15: tsbohemia.cz | E15: 零售/电商 | F15: Conexpro（捷克自有品牌） | G15: 否 | H15: 说明捷克接受自有品牌 | I15: — | J15: 官网 | K15: ★★ | L15: 未触达 | M15: 反向信号/2026-09
A16: Conexpro (GNT-IG 系列) | B16: 捷克 | D16: — | E16: 自有品牌 | F16: Conexpro | G16: 是 | H16: ⚠️价格地板（8口PoE DIN≈€55），别硬拼 | I16: — | J16: — | K16: ✕ | L16: 未触达 | M16: 反向信号/2026-09
A17: MADER.cz | B17: 捷克 | D17: mader.cz | E17: 电商 | F17: 工业PoE | G17: 否 | H17: 中性货试单 | I17: LT-IS6310GP-2GX8GT | J17: 官网 | K17: ★★ | L17: 未触达 | M17: 反向信号/2026-09
A18: IndustrialComms | B18: 英国 | D18: industrialcomms.com | E18: 专业分销 | F18: EtherWAN | G18: 否 | H18: ⭐英国T1：熟悉工业交换机，缺低价第二供应源 | I18: LT-IS6312XG-4XS8GT | J18: 官网+LinkedIn | K18: ★★★ | L18: 未触达 | M18: 反向信号/2026-09 | Q18: 交通/公用事业/监控
A19: AMG Systems | B19: 英国 | D19: — | E19: 品牌（竞品） | F19: AMG | G19: 是 | H19: 打其下游集成商 | I19: — | J19: — | K19: ★ | L19: 未触达 | M19: 反向信号/2026-09
A20: Switch SFP | B20: 英国 | D20: switchsfp.com | E20: 分销 | F20: Antaira | G20: 否 | H20: 同价位替代 | I20: LT-IS6312XG-4XS8GT | J20: sales@switchsfp.com | K20: ★★ | L20: 未触达 | M20: 反向信号/2026-09
A21: Millbeck | B21: 英国 | D21: millbeck.co.uk | E21: 分销 | F21: Teltonika（Diamond 最高级） | G21: 否 | H21: 他们只有8口→补16/24口与10G | I21: LT-IS6318XG-2XS16GT | J21: 官网 | K21: ★★★ | L21: 未触达 | M21: 反向信号/2026-09
A22: RSP Supply | B22: 美国 | D22: rspsupply.com | E22: 分销 | F22: Moxa 授权 | G22: 否 | H22: 中性货+价格；⚠️TAA项目不碰 | I22: LT-IS6312XGP-4XS8GT | J22: 官网 | K22: ★★ | L22: 未触达 | M22: 反向信号/2026-09
A23: 4D Controls | B23: 美国 | D23: 4dcontrols.com | E23: 工控二手/维修 | F23: Moxa（新机/二手/维修） | G23: 否 | H23: ⭐二手商缺新品供应，中性货最易成交 | I23: LT-IS6312XG-4XS8GT | J23: 官网 | K23: ★★★ | L23: 未触达 | M23: 反向信号/2026-09 | Q23: 工程师自营
A24: Motion (motionworld.com) | B24: 美国 | D24: motionworld.com | E24: 大分销 | F24: Moxa | G24: 否 | H24: 流程长，慢跟 | I24: LT-IS6312XG-4XS8GT | J24: 官网 | K24: ★ | L24: 未触达 | M24: 反向信号/2026-09
A25: Wireless Professional Solutions | B25: 澳洲 | D25: wisp.net.au | E25: 分销 | F25: PLANET 官方 | G25: 否 | H25: ANZ（T2）慢慢做 | I25: LT-IS6312XG-4XS8GT | J25: shop@wisp.net.au | K25: ★★ | L25: 未触达 | M25: 反向信号/2026-09
A26: eWorldMe | B26: 阿联酋 | D26: moxa.eworldme.com | E26: 分销 | F26: Moxa | G26: 否 | H26: MEA渠道（T2） | I26: LT-IS6312XG-4XS8GT | J26: 官网 | K26: ★★ | L26: 未触达 | M26: 反向信号/2026-09
A27: Gigamedia | B27: 法国 | D27: gigamedia.net | E27: 自有品牌（经Rexel销售） | F27: GGM 工业DIN系列 | G27: 是 | H27: ⭐OEM目标：明显不自产，走Rexel渠道 | I27: LT-IS6312XGP-4XS8GT | J27: 官网contact | K27: ★★★ | L27: 未触达 | M27: 反向信号/2026-09 | Q27: 100+员工、30年经验
A28: Rexel | B28: 法国/意大利 | D28: rexel.fr / rexel.it | E28: 大分销 | F28: Gigamedia | G28: 否 | H28: 渠道（通过Gigamedia或直供） | I28: LT-IS6328XGP-4XS24GT | J28: 官网 | K28: ★★ | L28: 未触达 | M28: 反向信号/2026-09 | Q28: 电气分销巨头
A29: Sphinx France | B29: 法国 | D29: sphinxfrance.com | E29: 专业分销 | F29: Moxa/Advantech/Perle/Terz | G29: 否 | H29: 第二供应源，48h交付+技术支持 | I29: LT-IS6328XGP-4XS24GT | J29: 官网 | K29: ★★★ | L29: 未触达 | M29: 反向信号/2026-09
A30: Inmac Wstore | B30: 法国 | D30: inmac-wstore.com | E30: B2B IT分销 | F30: STONET/PLANET/TRENDnet/Moxa/StarTech | G30: 否 | H30: 上架/中性货，SKU多 | I30: LT-IS6312XGP-4XS8GT | J30: 官网 | K30: ★★★ | L30: 未触达 | M30: 反向信号/2026-09 | Q30: Moxa EDS-G308 €298
A31: Direktronik AB | B31: 瑞典 | D31: direktronik.se | E31: 分销（品牌独立） | F31: N-net 等；已在卖带ERPS/SNMPv3的管理型 | G31: 否 | H31: 已卖ERPS管理型→补10G上行与PoE++ | I31: LT-IS6312XGP-4XS8GT-2BT | J31: 官网 | K31: ★★★ | L31: 未触达 | M31: 反向信号/2026-09 | Q31: 30+年，8口PoE管理型约€127
A32: Danbit | B32: 丹麦 | D32: danbit.dk | E32: 分销 | F32: 自有 + Moxa EDS-205 | G32: 部分 | H32: 已有PoE++(95W/口)线→补10G与24口 | I32: LT-IS6328XGP-4XS24GT-4BT | J32: 官网 | K32: ★★★ | L32: 未触达 | M32: 反向信号/2026-09
A33: Ditecom | B33: 西班牙 | C33: 马德里 | D33: ditecom.com | E33: 分销+网店 | F33: 工业管理型（EX-9911M环网） | G33: 否 | H33: 第二供应源；公开电话与邮箱 | I33: LT-IS6312XG-4XS8GT | J33: +34 91 528 54 37 / info@ditecom.com | K33: ★★★ | L33: 未触达 | M33: 反向信号/2026-09
A34: Ekanet | B34: 西班牙 | D34: ekanet.es | E34: 分销 | F34: PLANET 工业DIN（4–16口） | G34: 否 | H34: 中性货；他们价格带很低(€34–139) | I34: LT-IS6310GP-2GX8GT | J34: 官网 | K34: ★★★ | L34: 未触达 | M34: 反向信号/2026-09
A35: ecomshop | B35: 西班牙 | D35: ecomshop.es | E35: B2B批发 | F35: STONET/Teltonika/WI-TEK/Tachyon | G35: 否 | H35: 批发渠道，已在卖中国系品牌→可切 | I35: LT-IS6312XGP-4XS8GT | J35: 官网 | K35: ★★★ | L35: 未触达 | M35: 反向信号/2026-09 | Q35: B2B Mayoristas
A36: Cablewindow | B36: 西班牙 | C36: 马德里 | D36: cablewindow.com | E36: 分销 | F36: 工业DIN（管理型/PoE） | G36: 否 | H36: 第二供应源 | I36: LT-IS6312XGP-4XS8GT | J36: +34 917987780 | K36: ★★ | L36: 未触达 | M36: 反向信号/2026-09 | Q36: Calle Laguna del Marquesado 12
A37: atecnica.it | B37: 意大利 | D37: atecnica.it | E37: 电商 | F37: 自有 SF- 系列工业PoE | G37: 部分 | H37: 中性货/低价竞争（8口PoE 130W €71） | I37: LT-IS6312XGP-4XS8GT | J37: 官网 | K37: ★★ | L37: 未触达 | M37: 反向信号/2026-09
A38: Rexel Italia | B38: 意大利 | D38: rexel.it | E38: 大分销 | F38: Gigamedia | G38: 否 | H38: 渠道 | I38: LT-IS6328XGP-4XS24GT | J38: 官网 | K38: ★★ | L38: 未触达 | M38: 反向信号/2026-09
A39: STONET / Netis | B39: 中国（在欧销售） | D39: — | E39: 竞品（中国低价） | F39: STONET NIS 系列 | G39: 是 | H39: ⚠️价格地板；卖他们的欧洲商家=你的客户 | I39: — | J39: — | K39: 观察 | L39: 未触达 | M39: 反向信号/2026-09 | Q39: 经 ecomshop(ES)、Inmac(FR)
A40: WI-TEK | B40: 中国（在欧销售） | D40: — | E40: 竞品（中国低价） | F40: WI-PMS310GF（8GE PoE+2SFP，300W） | G40: 是 | H40: ⚠️同上 | I40: — | J40: — | K40: 观察 | L40: 未触达 | M40: 反向信号/2026-09 | Q40: 经 ecomshop(ES)
...

Sheet 欧洲街价锚点
A1: 品牌/型号 | B1: 规格 | C1: 渠道 | D1: 街价（含税/未税以渠道为准） | E1: 你的对标 SmartByte 型号 | F1: 你的卖价 | G1: 倍数
A2: ORing 8口 managed DIN（12/24/48V） | B2: 8×FE managed，IP30 | C2: spectra.de（德） | D2: €343 | E2: LT-IS6306G-2GX4GT（4GE+2SFP） | F2: $132 ≈ €122 | G2: —
A3: ORing 6口 lite-managed PoE | B3: 4FE PoE + 2 SFP | C3: spectra.de | D3: €363 | E3: LT-IS6310GP-2GX8GT（8GE PoE+2SFP） | F3: $143 ≈ €132 | G3: ≈1/2.8
A4: ORing 12口 Gb PoE managed | B4: 8GE+4GE PoE+2SFP | C4: spectra.de | D4: €1,043 | E4: LT-IS6312XGP-4XS8GT（8GE PoE+4×10G） | F4: $169 ≈ €156 | G4: ≈1/6.7
A5: ORing EN50155 12口 10G PoE | B5: M12，IP30 | C5: spectra.de | D5: €2,718 | E5: —（铁路线不打） | F5: — | G5: —
A6: PLANET IGS-5225-4T2S | B6: 4GE+2×1G/2.5G SFP | C6: fiber24 / shop4power | D6: €252 / €207 | E6: LT-IS6306G-2GX4GT | F6: $101 ≈ €93 | G6: ≈1/2.4
A7: PLANET IGS-5225-4P2S | B7: 4GE PoE + 2 SFP | C7: fiber24 | D7: €293 | E7: LT-IS6310GP-2GX8GT | F7: $110 ≈ €101 | G7: ≈1/2.9
A8: PLANET IGS-5225-8P2T2S | B8: 8 PoE | C8: fiber24 | D8: €469 | E8: LT-IS6312XGP-4XS8GT | F8: $130 ≈ €120 | G8: ≈1/3.9
A9: PLANET IGS-5225-8T2S2X | B9: 8GE+2SFP+2×10G SFP+ | C9: fiber24 | D9: €540 | E9: LT-IS6312XG-4XS8GT | F9: $118 ≈ €109 | G9: ≈1/5
A10: Moxa EDS-405A | B10: 5×FE managed，Turbo Ring | C10: TME（波）/ RSP（美） | D10: €429 / $654 | E10: LT-IS3210G-2GX8GT 或 LT-IS6310G | F10: $99 ≈ €91 | G10: ≈1/4.7
A11: StarTech IE-5G-INDUSTRIAL | B11: 5口非管理工业 | C11: 捷克电商 | D11: ≈€86–100（2,179–2,525 CZK） | E11: LT-IS3206G-2GX4GT | F11: $45 ≈ €42 | G11: （非管理，不比）
A12: TRENDnet TI-PG102 | B12: PoE++ | C12: 捷克电商 | D12: ≈€418（10,458 CZK） | E12: LT-IS6312XGP-4XS8GT-2BT | F12: $144 ≈ €133 | G12: ≈1/3.1
... A24: TP-Link Omada IES206GPP | B24: 6口Gb Easy Managed + PoE++，云管理 | C24: Omada 北欧站 | D24: （工业线新进入者） | E24: LT-IS6310GP-2GX8GT-2BT | F24: $124 ≈ €114 | G24: ⚠️威胁：云+品牌，打ERPS/CLI/无云锁定

Sheet 重点客户配货表
A1: 类别 | B1: SmartByte型号 | C1: 关键规格 | D1: ¥未税(2026.09.01-12.30) | E1: $进价(7.1) | F1: $建议卖价(+30%) | G1: ⭐主推客户
A2: 商业L2+ 走量 | B2: LT-S8328G-4GX24GT-S | C2: 24×GE + 4×1G/2.5G SFP（AC5爆款） | D2: 460 | E2: 65 | F2: 85 | G2: 2direct / Nedis
A3: 商业L2+ | B3: LT-S8310GP-2GX8GT | C3: 8×GE PoE + 4 SFP，120W | D3: 450 | E3: 63 | F3: 82 | G3: Nedis / Intos
A4: 商业L2+ | B4: LT-S8328GP-4GX24GT-S | C4: 24×GE PoE + 4 SFP，280W | D4: 750 | E4: 106 | F4: 138 | G4: 2direct / Intos
A5: 商业L2+ | B5: LT-S8328GP-4GX24GT | C5: 24×GE PoE + 4 SFP，440W | D5: 1200 | E5: 169 | F5: 220 | G5: Intos（对标其380W款）
A6: 商业L2+ ⭐ | B6: LT-S8328XG-4XS24GT-S | C6: 24×GE + 4×10G SFP+（AC5爆款） | D6: 710 | E6: 100 | F6: 130 | G6: ASSMANN / Nedis / IC Intracom
A7: 商业L2+ ⭐ | B7: LT-S8328XGP-4XS24GT-S | C7: 24×GE PoE + 4×10G SFP+，280W | D7: 1010 | E7: 142 | F7: 185 | G7: ASSMANN / IC Intracom
A8: 商业L2+ | B8: LT-S8352G-4GX48GT | C8: 48×GE + 4 SFP | D8: 1320 | E8: 186 | F8: 242 | G8: DDC / Intos
A9: 商业L2+ | B9: LT-S8352GP-4GX48GT | C9: 48×GE PoE + 4 SFP，440W | D9: 1720 | E9: 242 | F9: 315 | G9: DDC
A10: 商业L2+ | B10: LT-S8352XG-4XS48GT | C10: 48×GE + 4×10G SFP+ | D10: 1470 | E10: 207 | F10: 269 | G10: DDC
A11: 商业L2+ | B11: LT-S8352XGP-4XS48GT | C11: 48×GE PoE + 4×10G，440W/850W | D11: 1870 | E11: 263 | F11: 342 | G11: DDC / Intos
A12: 商业L3 | B12: LT-S8528XG-4XS24GT | C12: L3，24×GE + 4×10G | D12: 1500 | E12: 211 | F12: 274 | G12: DDC（他们没有L3）
A13: 商业L3 | B13: LT-S8528XGP-4XS24GT | C13: L3 PoE，400W | D13: 1900 | E13: 268 | F13: 348 | G13: DDC
... A30: 工业L3 | B30: LT-IS6528XGP-4XS24GT | C30: L3 24×GE PoE + 4×10G | D30: 2700 | E30: 380 | F30: 494 | G30: 工业L3项目

Sheet MikroTik全产品线
A1: 说明：来自仓库 MikroTik_L2Plus_Switches.xlsx 去重后 49 款（抓取值，可能有误）；'实测价' 列为 2026-09 官网核实值。
A2: 型号 | B2: 抓取价格 | C2: 实测价 ✅ | D2: 端口配置 | E2: 交换芯片 | F2: OS | G2: 工作温度 | H2: PoE 输出 | I2: PoE 预算 | J2: 分段/备注
A3: CRS106-1C-5S | B3: $89.00 | D3: 1x Combo (GbE/SFP), 5x SFP (1G) | E3: QCA8511 | F3: RouterOS v7 / SwOS | G3: -20°C to +60°C
A4: CRS112-8G-4S-IN | B4: $119.00 | D4: 8x GbE RJ45, 4x SFP (1G) | E4: QCA8513 | F4: RouterOS v7 / SwOS | G4: -20°C to +60°C
A5: CRS112-8P-4S-IN | B5: $209.00 | D5: 8x GbE RJ45, 4x SFP | E5: QCA8511 | F5: RouterOS | G5: -20°C to 60°C | H5: PoE (802.3af)
A6: CRS210-8G-2S+IN | B6: $229.00 | D6: 8x GbE RJ45, 2x SFP+ | E6: QCA8519-AC2C | F6: RouterOS | G6: -40°C to 70°C | H6: PoE (802.3af)
A7: CRS212-1G-10S-1S+IN | B7: $219.00 | D7: 1x GbE RJ45, 10x SFP, 1x SFP+ | E7: QCA8519 | F7: RouterOS | G7: -40°C to 70°C
A8: CRS304-4XG-IN | B8: $199.00 | D8: 4x 10GbE RJ45 | E8: 98DX2528 | F8: RouterOS v7 | G8: -40°C to 70°C | H8: PoE (802.3af)
A9: CRS305-1G-4S+IN | B9: $149.00 | D9: 1x GbE RJ45, 4x SFP+ | E9: 98DX3236 | F9: RouterOS / SwitchOS | G9: -40°C to 70°C | H9: PoE (802.3af)
A10: CRS305-1G-4S+OUT | B10: $229.00 | E10: 98DX226S | F10: RouterOS v7 / SwOS | G10: -40°C to 70°C | H10: PoE (802.3af)
A11: CRS309-1G-8S+IN | B11: $269.00 | D11: 1x GbE RJ45, 8x SFP+ | E11: 98DX8208 | F11: RouterOS / SwitchOS | G11: -40°C to 70°C | H11: PoE (802.3af) | J11: 全光/高速，不打
A12: CRS310-1G-5S-4S+IN | B12: $199.00 | D12: 1x GbE RJ45, 5x SFP, 5x SFP+ | E12: 98DX226S | F12: RouterOS v7 / SwitchOS | G12: -40°C to 70°C | H12: PoE (802.3af)
A13: CRS310-1G-5S-4S+OUT | B13: $249.00 | D13: 5x SFP+ | E13: 98DX226S | F13: RouterOS v7 / SwitchOS | G13: -40°C to 70°C | H13: PoE (802.3af)
A14: CRS310-8G+2S+IN | B14: $149.00 | D14: 8x 2.5GbE RJ45, 2x SFP+ (10G) | E14: 98DX226S | F14: RouterOS v7 / SwOS | G14: -40°C to +60°C
A15: CRS312-4C+8XG | B15: $349.00 | D15: 4x Combo (10G SFP+/RJ45), 8x 10GbE RJ45 | E15: 98DX8212 | F15: RouterOS v7 / SwOS | G15: -20°C to +60°C | J15: 全光/高速，不打
A16: CRS312-4C+8XG-RM | B16: $699.00 | D16: 8x 10GbE RJ45, 4x Combo | E16: 98DX8212 | F16: RouterOS v7 / SwitchOS | G16: -30°C to 70°C | J16: 全光/高速，不打
A17: CRS317-1G-16S+RM | B17: $499.00 | D17: 10x GbE RJ45, 16x SFP+ | E17: 98DX8216 | F17: RouterOS / SwitchOS | G17: -20°C to 60°C | J17: 全光/高速，不打
A18: CRS318-16P-2S+OUT | B18: $279.00 | D18: 16x GbE RJ45 | E18: 98DX226S | F18: RouterOS / SwitchOS | G18: -40°C to 70°C | H18: PoE (802.3af)
A19: CRS318-16P-2S+RM | B19: $329.00 | D19: 16x GbE RJ45 (PoE-out), 2x SFP+ (10G) | E19: 98DX3236 | F19: RouterOS v7 / SwOS | G19: -20°C to +60°C | H19: PoE+ (802.3af/at/bt) | I19: 300 W
A20: CRS318-1F | B20: $169.00 | D20: 15x 100M Fiber | E20: 98DX224S | F20: RouterOS / SwitchOS | G20: -40°C to 70°C | H20: Passive PoE
A21: CRS318-1Fi-15Fr-2S | B21: $225.00 | D21: 15x 100M Fiber, 1x 1G Fiber, 2x SFP | E21: 98DX3236 | F21: RouterOS v7 / SwOS | G21: -20°C to +70°C
A22: CRS320-8P-8B-4S+RM | B22: $489.00 | D22: 17x GbE RJ45, 4x SFP+ | E22: 98DX226S | F22: RouterOS v7 / SwitchOS | G22: -10°C to 50°C | H22: PoE+ (802.3bt)
A23: CRS326-24G-2S+IN | B23: $199.00 | D23: 24x GbE RJ45, 2x SFP+ (10G) | E23: 98DX3236 | F23: RouterOS v7 / SwOS | G23: -40°C to +60°C
A24: CRS326-24G-2S+RM | B24: $219.00 | C24: 209 | D24: 24x GbE RJ45, 2x SFP+ (10G) | E24: 98DX3236 | F24: RouterOS v7 / SwOS | G24: -20°C to +60°C
A25: CRS326-24S+2Q+RM | B25: $599.00 | D25: 24x SFP+ | E25: 98DX8332 | F25: RouterOS v7 / SwitchOS | G25: -20°C to 60°C | J25: 全光/高速，不打
A26: CRS326-4C+20G+2Q+RM | B26: $999.00 | D26: 5x GbE RJ45, 20x 2.5GbE, 4x Combo | E26: 98DX8332 | F26: RouterOS v7 | G26: -20°C to 60°C
A27: CRS326-4C+20G+2S+RM | B27: $239.00 | D27: 4x Combo (GbE/SFP), 20x GbE RJ45, 2x SFP+ (10G) | E27: 98DX3236 | F27: RouterOS v7 / SwOS | G27: -20°C to +60°C
A28: CRS328-24P-4S+RM | B28: $489.00 | C28: 489 | D28: 24x GbE RJ45, 4x SFP+ | E28: 98DX3236 | F28: RouterOS / SwitchOS | G28: -20°C to 60°C | H28: PoE (802.3af)
A29: CRS328-4C-20S-4S+RM | B29: $449.00 | D29: 4x Combo, 20x SFP, 4x SFP+ | E29: 98DX3236 | F29: RouterOS / SwitchOS | G29: -20°C to 60°C | J29: 全光/高速，不打
A30: CRS332-32S+RM | B30: $749.00 | D30: 32x SFP+ (10G), 6x Combo (SFP+/RJ45) | E30: 98DX8332 | F30: RouterOS v7 / SwOS | G30: -20°C to +60°C | J30: 全光/高速，不打
A31: CRS354-48G-4S+2Q+RM | B31: $599.00 | C31: 599 | D31: 48x GbE RJ45, 4x SFP+ | E31: 98DX3257 | F31: RouterOS v7 / SwitchOS | G31: -20°C to 60°C
A32: CRS354-48P-4S+2Q+RM | B32: $999.00 | D32: 4x SFP+ | E32: 98DX3257 | F32: RouterOS v7 / SwitchOS | G32: -20°C to 60°C | H32: PoE (802.3af)
A33: CRS418-8P-8G-2S+5 | B33: $499.00 | D33: 16x GbE RJ45, 2x SFP+ | E33: 98DX226S | F33: RouterOS v7 | G33: -20°C to 70°C | H33: PoE (802.3af)
A34: CRS418-8P-8G-2S+RM | B34: $449.00 | D34: 16x GbE RJ45, 2x SFP+ | E34: 98DX226S | F34: RouterOS v7 | G34: -20°C to 70°C | H34: PoE (802.3af)
A35: CRS504-4XQ-IN | B35: $799.00 | D35: 4x QSFP28 | E35: 98DX4310 | F35: RouterOS v7 | G35: -40°C to 70°C | J35: 全光/高速，不打
A36: CRS504-4XQ-OUT | B36: $899.00 | D36: 100x GbE RJ45, 4x QSFP28 | E36: 98DX4310 | F36: RouterOS v7 | G36: -40°C to 70°C | H36: PoE+ (802.3bt) | J36: 全光/高速，不打
A37: CRS510-8XS-2XQ-IN | B37: $999.00 | D37: 8x SFP+, 2x QSFP28 | E37: 98DX4310 | F37: RouterOS v7 | G37: -40°C to 70°C | J37: 全光/高速，不打
A38: CRS518-16XS-2XQ-RM | B38: $1595.00 | D38: 16x SFP+, 2x QSFP28 | E38: 98DX8525 | F38: RouterOS v7 | G38: -40°C to 70°C | J38: 全光/高速，不打
A39: CRS520-4XS-16XQ-RM | B39: $2195.00 | D39: 100x GbE RJ45, 4x SFP+, 16x QSFP28 | E39: 98CX8410 | F39: RouterOS v7 | G39: -20°C to 50°C | J39: 全光/高速，不打
A40: CRS804-4DDQ- | B40: $1295.00 | E40: 98DX7335 | F40: RouterOS v7 | G40: -10°C to 60°C
...

Sheet 合规文件清单
A1: # | B1: 文件/证书 | C1: 适用地区 | D1: 必备性 | E1: 谁出具 | F1: 你目前状态 | G1: 怎么补 | H1: 对客户的价值
A2: 1 | B2: EN 55032 / EN 55035 EMC 测试报告 | C2: EU/UK | D2: 必备 | E2: 第三方实验室 | F2: 需向 SmartByte 要带型号的完整报告 | G2: 向工厂索取原件，核对型号/日期/实验室资质 | H2: CE 与 UKCA 的技术基础
A3: 2 | B3: EN IEC 62368-1 安全测试报告（LVD） | C3: EU/UK | D3: 必备 | E3: 第三方实验室 | F3: 需确认是 62368-1 而非 60950-1 | G3: 索取；若仍是旧标准需补测 | H3: 客户合规部第一件事就是查这个
A4: 3 | B4: RoHS 10 项检测报告 + EN IEC 63000 技术文档 | C4: EU/UK | D4: 必备 | E4: 实验室 | F4: 有声明，需报告原件 | G4: 索取报告原件 | H4: 无报告=无 CE
A5: 4 | B5: REACH SVHC 声明 / SCIP 通报数据 | C5: EU | D5: 必备 | E5: 供应链 | F5: ⚠️ SCIP 多半没有 | G5: 要 SVHC 清单；>0.1% 需物料数据 | H5: 缺少会被海关/市场监管拦下
A6: 5 | B6: EU DoC（欧盟符合性声明）模板 | C6: EU | D6: 必备 | E6: 制造商（贴牌客户） | F6: 需工厂提供可改写模板 | G6: 向工厂要模板 + 客户签署 | H6: 没有 DoC 就不能贴 CE
A7: 6 | B7: EU Authorised Representative（欧盟授权代表） | C7: EU | D7: 必备（非欧盟制造商） | E7: 客户指定 | F7: 由客户承担 | G7: 可协助对接第三方 AR 服务（增值） | H7: OEM 谈判最常见的断点
A8: 7 | B8: WEEE 注册号（DE stiftung ear / FR / IT / ES / NL / SE / PL BDO） | C8: EU各国 | D8: 必备 | E8: 客户（品牌方） | F8: 客户持有 | G8: 我们提供型号重量与材料拆分数据 | H8: 没有注册号不能在该国销售
A9: 8 | B9: 包装法：德国 VerpackG LUCID + 双元系统；法国 EPR；PPWR (EU)2025/40 | C9: EU | D9: 必备 | E9: 客户 | F9: 客户持有 | G9: 我们提供包装材料与重量数据 | H9: 德国查得最严
A10: 9 | B10: ErP (EU)2019/1782 外置电源能效（等同 DoE Level VI） | C10: EU/US | D10: 带适配器时必备 | E10: 实验室 | F10: 需确认适配器证书 | G10: 索取适配器证书 | H10: 外置电源没证=整机不能上架
A11: 10 | B11: CRA (EU)2024/2847 技术文档（交换机=Annex III Class I） | C11: EU | D11: 2027-12-11 起必备 | E11: 制造商（客户）+ 我们提供输入 | F11: ⚠️ 基本空白 | G11: SBOM + 漏洞政策 + 更新承诺 + EN 18031 路线图 | H11: ⭐ 2026-2027 最有杀伤力的差异化
A12: 11 | B12: SBOM（SPDX / CycloneDX） | C12: EU/UK/US | D12: CRA 必备 | E12: 工厂 | F12: ⚠️ 没有 | G12: 向工厂索取并约定每版更新 | H12: 客户合规部无法自行生成
A13: 12 | B13: 漏洞处理政策（接收渠道/响应SLA/协调披露） | C13: EU | D13: CRA 必备 | E13: 工厂 + 我们 | F13: ⚠️ 没有 | G13: 起草 policy + security@ 邮箱 + 响应时限 | H13: 24h/72h 通报义务的基础
... A26: 25 | B26: 产品责任保险 | C26: EU/US | D26: 大客户常要求 | E26: 客户/双方 | F26: 需确认 | G26: 客户投保或双方共保 | H26: 贴牌客户作为制造商通常需要

Sheet 开发系统-节奏与KPI
A1: 周期 | B1: 动作 | C1: 数量/频率 | D1: 负责人 | E1: 看什么数 | F1: 备注
A2: 每日 | B2: 新进名单+打分入池 | C2: 15-20 家 | D2: 开发 | E2: 新增名单 | F2: 宁可精准300不要垃圾3000
A3: 每日 | B3: LinkedIn 邀请 | C3: 15-20（每周总量≤100） | D3: 开发 | E3: 接受率≥35% | F3: 新号前两周每天≤10
A4: 每日 | B4: 首触/跟进 | C4: 20-30 | D4: 开发 | E4: 回复率 | F4: LinkedIn+邮件混合
A5: 每日 | B5: 处理回复 | C5: 2 小时内 | D5: 开发 | E5: — | F5: 超过2小时转化率腰斩
A6: 每日 | B6: 更新 CRM / 明日跟进 | C6: 下班前 | D6: 开发 | E6: — | F6: 客户不得停在'已触达'>21天
A7: 每周二/四 | B7: 内容发布 | C7: 各 1 条 | D7: 内容 | E7: 互动率 | F7: 技术型 > 广告型
A8: 每周五 | B8: 漏斗复盘 | C8: 1 小时 | D8: 负责人 | E8: 全漏斗 | F8: 砍掉最差管道的10%动作
A9: 每周五 | B9: 周报 | C9: 1 篇 | D9: 负责人 | E9: — | F9: 见手册附录A
A10: 每月 | B10: A 类深挖（找老板/技术总监） | C10: 30 家 | D10: 开发 | E10: A类池 40-60 家 | F10: 定制化技术资料
A11: 每月 | B11: 线上 demo / POC 复盘 | C11: 2 次 | D11: 技术 | E11: POC 通过率
A12: 每月 | B12: 案例或技术文章 | C12: 1 篇 | D12: 内容 | E12: — | F12: 累计12篇/年
A13: 每月 | B13: 渠道价格与竞品复核 | C13: 1 次 | D13: 负责人 | E13: —
A14: 每季 | B14: 展会或客户拜访 | C14: 1 次 | D14: 负责人 | E14: 有效名片数 | F14: 会前40家预约会
A15: 每季 | B15: 产品-市场匹配回顾 | C15: 1 次 | D15: 负责人 | E15: 缺口台账频次 | F15: 同一需求出现3次→向SmartByte提案
A16: 每年 | B16: 展会 | C16: 2-3 次 | D16: 负责人 | E16: — | F16: MUM / embedded world / Intertraffic 优先
A17: 每年 | B17: 与 SmartByte 年度共创会 | C17: 1 次 | D17: 负责人 | E17: 新品转化数 | F17: 把客户缺口变明年新品
A19: 指标 | B19: 起步期(月) | C19: 稳定期(月)
A20: 新增名单 | B20: 300-400 | C20: 200-300
A21: 触达次数 | B21: 500-600 | C21: 400-500
A22: LinkedIn 邀请 | B22: 250-300 | C22: 200-250
A23: 邮件发送 | B23: 400-600 | C23: 400-600
A24: 邀请接受率 | B24: — | C24: ≥35%
A25: 邮件回复率 | B25: — | C25: ≥6%
A26: 月度漏斗 | B26: 400触达→30回复→8技术对话→6样机→8报价→1-2首单
A27: 12个月目标 | B27: 新客户15-25家(OEM 3-5家) / 出货8-15k台 / 复购率≥50%
A28: 预算 轻模式 | B28: ≈ US$27k/年
A29: 预算 标准模式 | B29: ≈ US$87k/年（含参展+本地BD）
A30: ROI门槛 | B30: 1个OEM客户 = 年3k台 × 毛利$15 = $45k

Sheet MikroTik出口地(Comtrade2024)
A1: 说明：UN Comtrade，Reporter=Latvia(428)，HS 851762（交换/路由设备），Export，2024，FOB USD。MikroTik 占拉脱维亚该税号出口 3/4 以上，可视为 MikroTik 分销商进货地图。全球合计 USD 422,324,814。
A2: 排名 | B2: 国家/地区 | C2: M49 代码 | D2: 区域 | E2: 出口额 USD | F2: 占全球 % | G2: 备注
A3: 1 | B3: 美国 | C3: 842 | D3: 北美 | E3: 50994438 | F3: =E3/422324814 | G3: 对华关税约 37.5%（2026-09）
A4: 2 | B4: 阿联酋(转口枢纽) | C4: 784 | D4: 中东/土耳其 | E4: 43018484 | F4: =E4/422324814 | G4: 转口枢纽→中东/非洲/南亚
A5: 3 | B5: 波兰 | C5: 616 | D5: 欧洲 | E5: 34368342 | F5: =E5/422324814 | G5: 欧洲第一 MikroTik 国
A6: 4 | B6: 立陶宛(波罗的海分销枢纽) | C6: 440 | D6: 欧洲 | E6: 32525290 | F6: =E6/422324814 | G6: 波罗的海分销枢纽
A7: 5 | B7: 捷克 | C7: 203 | D7: 欧洲 | E7: 21822977 | F7: =E7/422324814 | G7: WISP 密度极高
A8: 6 | B8: 德国 | C8: 276 | D8: 欧洲 | E8: 16002618 | F8: =E8/422324814
A9: 7 | B9: 中国香港(转口枢纽) | C9: 344 | D9: 亚太 | E9: 15962714 | F9: =E9/422324814 | G9: 转口枢纽→东南亚/南亚
A10: 8 | B10: 南非 | C10: 710 | D10: 非洲 | E10: 11426199 | F10: =E10/422324814
A11: 9 | B11: 印度尼西亚 | C11: 360 | D11: 亚太 | E11: 11250898 | F11: =E11/422324814
A12: 10 | B12: 哈萨克斯坦 | C12: 398 | D12: 独联体/中亚 | E12: 10925270 | F12: =E12/422324814
A13: 11 | B13: 英国 | C13: 826 | D13: 欧洲 | E13: 8784753 | F13: =E13/422324814
A14: 12 | B14: 爱沙尼亚 | C14: 233 | D14: 欧洲 | E14: 8754532 | F14: =E14/422324814 | G14: 波罗的海分销枢纽
A15: 13 | B15: 乌克兰 | C15: 804 | D15: 欧洲 | E15: 8206878 | F15: =E15/422324814
A16: 14 | B16: 意大利 | C16: 380 | D16: 欧洲 | E16: 8186541 | F16: =E16/422324814
A17: 15 | B17: 土耳其 | C17: 792 | D17: 中东/土耳其 | E17: 7652474 | F17: =E17/422324814 | G17: 你已有 NMS 客户
A18: 16 | B18: 西班牙 | C18: 724 | D18: 欧洲 | E18: 7284155 | F18: =E18/422324814
A19: 17 | B19: 荷兰 | C19: 528 | D19: 欧洲 | E19: 6532562 | F19: =E19/422324814
A20: 18 | B20: 巴西 | C20: 76 | D20: 拉美 | E20: 5655456 | F20: =E20/422324814
A21: 19 | B21: 奥地利 | C21: 40 | D21: 欧洲 | E21: 4567730 | F21: =E21/422324814
A22: 20 | B22: 新加坡 | C22: 702 | D22: 亚太 | E22: 4496379 | F22: =E22/422324814 | G22: 转口枢纽
A23: 21 | B23: 中国大陆 | C23: 156 | D23: 亚太 | E23: 4493322 | F23: =E23/422324814
A24: 22 | B24: 加拿大 | C24: 124 | D24: 北美 | E24: 4469245 | F24: =E24/422324814
A25: 23 | B25: 哥伦比亚 | C25: 170 | D25: 拉美 | E25: 3752926 | F25: =E25/422324814
A26: 24 | B26: 保加利亚 | C26: 100 | D26: 欧洲 | E26: 3606615 | F26: =E26/422324814
A27: 25 | B27: 澳大利亚 | C27: 36 | D27: 亚太 | E27: 3596152 | F27: =E27/422324814
A28: 26 | B28: 匈牙利 | C28: 348 | D28: 欧洲 | E28: 3207035 | F28: =E28/422324814
A29: 27 | B29: 瑞典 | C29: 752 | D29: 欧洲 | E29: 3137243 | F29: =E29/422324814
A30: 28 | B30: 越南 | C30: 704 | D30: 亚太 | E30: 2733552 | F30: =E30/422324814
A31: 29 | B31: 智利 | C31: 152 | D31: 拉美 | E31: 2721330 | F31: =E31/422324814
A32: 30 | B32: 秘鲁 | C32: 604 | D32: 拉美 | E32: 2713158 | F32: =E32/422324814
A33: 31 | B33: 泰国 | C33: 764 | D33: 亚太 | E33: 2464546 | F33: =E33/422324814
A34: 32 | B34: 希腊 | C34: 300 | D34: 欧洲 | E34: 2308883 | F34: =E34/422324814
... A65: 63 | B65: 白俄罗斯 | C65: 112 | D65: 独联体/中亚 | E65: 3144 | F65: =E65/422324814
B66: 其他未查询国家（合计约 90 国） | E66: =422324814-SUM(E3:E65) | F66: =E66/422324814 | G66: 余量
B67: 全球合计 | E67: 422324814 | F67: 1
A69: 区域汇总
B70: 区域 | E70: 出口额 USD | F70: 占全球 %
B71: 欧洲 | E71: =SUMIF(D3:D65,"欧洲",E3:E65) | F71: =E71/422324814
...

Sheet 落地价与关税
A1: 落地价计算器（不含 VAT）。黄色格可改。美国关税 2025–2026 变动频繁，报价前按 HTS 8517.62.0020 现查。
A2: 参数 | B2: 值
A3: 你的售价 USD (EXW/FOB) | B3: 130
A4: 海运摊销 USD/台 | B4: 6
A5: 对比：CRS326 MSRP | B5: 209
A6: 对比：CSS326 MSRP | B6: 159
A8: 目的地 | B8: 中国产 HS 8517.62 关税 | C8: 依据（2026-09） | D8: 落地价 USD | E8: vs CRS326 | F8: vs CSS326 | G8: 打法
A9: 欧盟 | B9: 0 | C9: ITA 信息技术协定 0% | D9: =ROUND(($B$3+$B$4)*(1+B9),0) | E9: =D9/$B$5-1 | F9: =D9/$B$6-1 | G9: 价格+功能双打
A10: 英国 | B10: 0 | C10: ITA 0%；UKCA 你已有 | D10: =ROUND(($B$3+$B$4)*(1+B10),0) | E10: =D10/$B$5-1 | F10: =D10/$B$6-1 | G10: 价格+功能双打
A11: 美国（现状） | B11: 0.375 | C11: 301 List 3 25% + 2026-07-24 起强迫劳动分级中国档 12.5% | D11: =ROUND(($B$3+$B$4)*(1+B11),0) | E11: =D11/$B$5-1 | F11: =D11/$B$6-1 | G11: 只卖差异化：工业/PoE++/ERPS/串口/5年保修
A12: 美国（若叠加 10% 对华互惠层） | B12: 0.475 | C12: 部分来源称对华 10% 互惠层仍在（至 2026-11-10），报关行确认 | D12: =ROUND(($B$3+$B$4)*(1+B12),0) | E12: =D12/$B$5-1 | F12: =D12/$B$6-1 | G12: 同上
A13: 澳大利亚 | B13: 0 | C13: ChAFTA 0%；需 RCM | D13: =ROUND(($B$3+$B$4)*(1+B13),0) | E13: =D13/$B$5-1 | F13: =D13/$B$6-1 | G13: 价格+功能
A14: 阿联酋 | B14: 0.05 | C14: GCC 统一关税 5%（部分 IT 设备 0%） | D14: =ROUND(($B$3+$B$4)*(1+B14),0) | E14: =D14/$B$5-1 | F14: =D14/$B$6-1 | G14: 枢纽分销商 house brand
A15: 加拿大 | B15: 0 | C15: MFN 0%，无 301 | D15: =ROUND(($B$3+$B$4)*(1+B15),0) | E15: =D15/$B$5-1 | F15: =D15/$B$6-1 | G15: 随美国客户但价格优势保留
A16: 土耳其 | B16: 0 | C16: 欧盟关税同盟，ITA 0%（另有本地附加税，需核） | D16: =ROUND(($B$3+$B$4)*(1+B16),0) | E16: =D16/$B$5-1 | F16: =D16/$B$6-1 | G16: 复制 NMS 案例
A18: 负数 = 比 MikroTik 便宜；正数 = 比 MikroTik 贵。

Sheet MikroTik关键事实(实测)
A1: 项目 | B1: CSS326-24G-2S+RM | C1: CRS326-24G-2S+RM | D1: CRS328-24P-4S+RM | E1: CSS610-8G-2S+IN | F1: 来源
A2: MSRP | B2: $159 | C2: $209 | D2: $489 | E2: $119 | F2: mikrotik.com 产品页 2026-09
A3: 操作系统 | B3: SwOS only (v2.19) | C3: RouterOS L5 / SwOS 双启动 (7.24.4) | D3: RouterOS L5 / SwOS 双启动 | E3: SwOS Lite (v2.21) | F3: 同上
A4: 交换芯片 | B4: 98DX3216 | C4: 98DX3236 | D4: 98DX3236 | E4: 88E6193X | F4: 同上
A5: CPU / RAM / Flash | B5: — / — / 2MB | C5: ARM 2×800MHz / 512MB / 16MB | D5: ARM 1×800MHz / 512MB / 16MB | E5: — / — / 64KB | F5: 同上
A6: 端口 | B6: 24G + 2×SFP+ | C6: 24G + 2×SFP+ | D6: 24×PoE-out af/at + 4×SFP+ | E6: 8G + 2×SFP+ | F6: 同上
A7: PoE-out | B7: 无 | C7: 无 | D7: 450W 总预算(3×150W/8口)，30W/口，无 802.3bt | E7: 无 | F7: 同上
A8: Console | B8: 无 | C8: RJ45 | D8: RJ45 | E8: 无 | F8: 同上
A9: 温度 | B9: -20~70°C | C9: -40~60°C | D9: -20~60°C | E9: -20~60°C | F9: 同上
A10: 供电 | B10: 10–30V DC jack / 被动 PoE-in | C10: 10–30V DC jack / 被动 PoE-in | D10: 内置 500W PSU | E10: 12–57V DC / 被动 PoE-in | F10: 同上
A11: 认证 | B11: CE, EAC, RoHS | C11: CE, EAC, RoHS | D11: CE, EAC, RoHS | E11: CE, EAC, RoHS | F11: 同上（均无 UL/FCC 列出）
A12: MTBF | B12: ~200k h @25°C | C12: ~200k h | D12: ~200k h | E12: ~200k h | F12: 同上
... A17: RouterOS 强项(承认) | B17: — | C17: API、REST API(v7.1+)、脚本、Winbox、The Dude、bandwidth-test/traffic-generator、LLDP/CDP/MNDP | D17: 同左 | E17: — | F17: RouterOS 文档

Sheet SmartByte关键SKU
A1: 系列 | B1: 型号 | C1: 描述 | D1: 进价 RMB | E1: ≈USD | F1: 售价 USD (+加价率) | G1: 备注
A2: 商业 L2+ | B2: LT-S8328XG-4XS24GT-S | C2: 24G + 4×SFP+ 1/2.5/10G；0~50°C；3年 | D2: 710 | E2: =IF(D2="","",ROUND(D2/参数!$B$2,0)) | F2: =IF(D2="","",ROUND(D2/参数!$B$2*(1+参数!$B$3),0)) | G2: 对标 CSS326/CRS326 主力
A3: 商业 L2+ | B3: LT-S8328XGP-4XS24GT-S | C3: 24×PoE + 4×SFP+ 10G；280W | D3: 1010 | E3: =IF(D3="","",ROUND(D3/参数!$B$2,0)) | F3: =IF(D3="","",ROUND(D3/参数!$B$2*(1+参数!$B$3),0)) | G3: 对标 CRS328-24P（预算差）
A4: 商业 L2+ | B4: LT-S8328G-4GX24GT-S | C4: 24G + 4×1G/2.5G SFP | D4: 460 | E4: =IF(D4="","",ROUND(D4/参数!$B$2,0)) | F4: =IF(D4="","",ROUND(D4/参数!$B$2*(1+参数!$B$3),0))
A5: 商业 L2+ | B5: LT-S8328GP-4GX24GT | C5: 24×PoE + 4×2.5G SFP；440W | D5: 1200 | E5: =IF(D5="","",ROUND(D5/参数!$B$2,0)) | F5: =IF(D5="","",ROUND(D5/参数!$B$2*(1+参数!$B$3),0))
A6: 商业 L2+ | B6: LT-S8310G-2GX8GT | C6: 8G + 2×2.5G SFP | D6: 380 | E6: =IF(D6="","",ROUND(D6/参数!$B$2,0)) | F6: =IF(D6="","",ROUND(D6/参数!$B$2*(1+参数!$B$3),0)) | G6: 成本回落前暂停出货
A7: 商业 L2+ | B7: LT-S8310GP-2GX8GT | C7: 8×PoE(120W) + 2×2.5G SFP | D7: 450 | E7: =IF(D7="","",ROUND(D7/参数!$B$2,0)) | F7: =IF(D7="","",ROUND(D7/参数!$B$2*(1+参数!$B$3),0))
A8: 商业 L2+ | B8: LT-S8352XG-4XS48GT | C8: 48G + 4×SFP+ 10G | D8: 1470 | E8: =IF(D8="","",ROUND(D8/参数!$B$2,0)) | F8: =IF(D8="","",ROUND(D8/参数!$B$2*(1+参数!$B$3),0))
A9: 商业 L2+ | B9: LT-S8352XGP-4XS48GT | C9: 48×PoE + 4×SFP+ 10G；440W/850W | D9: 1870 | E9: =IF(D9="","",ROUND(D9/参数!$B$2,0)) | F9: =IF(D9="","",ROUND(D9/参数!$B$2*(1+参数!$B$3),0))
A10: 商业 L3 | B10: LT-S8528XG-4XS24GT | C10: 24G + 4×SFP+；L3 (RIP/OSPF/IS-IS/BGP/VRRP) | D10: 1500 | E10: =IF(D10="","",ROUND(D10/参数!$B$2,0)) | F10: =IF(D10="","",ROUND(D10/参数!$B$2*(1+参数!$B$3),0)) | G10: PoE 版 1900
A11: 商业 L3 | B11: LT-S8528XG-4XS16GX8GC | C11: 16×SFP + 8 Combo + 4×SFP+；L3 | D11: 2100 | E11: =IF(D11="","",ROUND(D11/参数!$B$2,0)) | F11: =IF(D11="","",ROUND(D11/参数!$B$2*(1+参数!$B$3),0))
A12: 商业 L3 | B12: LT-S8552XG-4XS48GT | C12: 48G + 4×SFP+；L3 | D12: 2600 | E12: =IF(D12="","",ROUND(D12/参数!$B$2,0)) | F12: =IF(D12="","",ROUND(D12/参数!$B$2*(1+参数!$B$3),0)) | G12: PoE 版 3100
A13: 工业 L2+ | B13: LT-IS6306G-2GX4GT | C13: 4G + 2×SFP；DIN；-40~75°C；5年 | D13: 660 | E13: =IF(D13="","",ROUND(D13/参数!$B$2,0)) | F13: =IF(D13="","",ROUND(D13/参数!$B$2*(1+参数!$B$3),0)) | G13: PoE 720 / PoE++ 820；Frank 6口对位
A14: 工业 L2+ | B14: LT-IS6310G-2GX8GT | C14: 8G + 2×2.5G SFP | D14: 700 | E14: =IF(D14="","",ROUND(D14/参数!$B$2,0)) | F14: =IF(D14="","",ROUND(D14/参数!$B$2*(1+参数!$B$3),0)) | G14: PoE 780 / PoE++ 880
A15: 工业 L2+ | B15: LT-IS6312G-4GX8GT | C15: 8G + 4×2.5G SFP | D15: 740 | E15: =IF(D15="","",ROUND(D15/参数!$B$2,0)) | F15: =IF(D15="","",ROUND(D15/参数!$B$2*(1+参数!$B$3),0)) | G15: PoE 820 / -2BT 920；Frank 12口对位
A16: 工业 L2+ | B16: LT-IS6312XG-4XS8GT | C16: 8G + 4×SFP+ 10G | D16: 840 | E16: =IF(D16="","",ROUND(D16/参数!$B$2,0)) | F16: =IF(D16="","",ROUND(D16/参数!$B$2*(1+参数!$B$3),0)) | G16: PoE 920 / -2BT 1020
A17: 工业 L2+ | B17: LT-IS6312GP-4GX8GT-8BT | C17: 8×90W PoE++ (480W) + 4×2.5G SFP；52–57VDC | E17: =IF(D17="","",ROUND(D17/参数!$B$2,0)) | F17: =IF(D17="","",ROUND(D17/参数!$B$2*(1+参数!$B$3),0)) | G17: 价格表未列，官网有；询价
A18: 工业 L2+ | B18: LT-IS6316XG-4XS4GX8GT | C18: 8G + 4×SFP + 4×SFP+ | D18: 1400 | E18: =IF(D18="","",ROUND(D18/参数!$B$2,0)) | F18: =IF(D18="","",ROUND(D18/参数!$B$2*(1+参数!$B$3),0))
A19: 工业 L2+ | B19: LT-IS6318G-2GX16GT | C19: 16G + 2×SFP | D19: 1180 | E19: =IF(D19="","",ROUND(D19/参数!$B$2,0)) | F19: =IF(D19="","",ROUND(D19/参数!$B$2*(1+参数!$B$3),0)) | G19: PoE 1340
A20: 工业 L2+ | B20: LT-IS6318XGP-2XS16GT | C20: 16×PoE + 2×SFP+ | D20: 1660 | E20: =IF(D20="","",ROUND(D20/参数!$B$2,0)) | F20: =IF(D20="","",ROUND(D20/参数!$B$2*(1+参数!$B$3),0))
A21: 工业 L2+ DI/DO/RS485 | B21: LT-IS6320G-4GX16GT-D | C21: 16G + 4×SFP + DI/DO/RS485 | D21: 1560 | E21: =IF(D21="","",ROUND(D21/参数!$B$2,0)) | F21: =IF(D21="","",ROUND(D21/参数!$B$2*(1+参数!$B$3),0)) | G21: PoE 1760 / -4BT 1960；ITS/SCADA 场景
A22: 工业 L2+ DI/DO/RS485 | B22: LT-IS6328XG-4XS24GT-D | C22: 24G + 4×SFP+ 10G + DI/DO/RS485 | D22: 1960 | E22: =IF(D22="","",ROUND(D22/参数!$B$2,0)) | F22: =IF(D22="","",ROUND(D22/参数!$B$2*(1+参数!$B$3),0)) | G22: PoE 2200 / -4BT 2400
A23: 工业 L2+ DI/DO/RS485 | B23: LT-IS6328XG-4XS16GX8GC-D | C23: 16×SFP + 8 Combo + 4×SFP+ + DI/DO | D23: 2650 | E23: =IF(D23="","",ROUND(D23/参数!$B$2,0)) | F23: =IF(D23="","",ROUND(D23/参数!$B$2*(1+参数!$B$3),0)) | G23: vs CRS328-4C-20S-4S+ $299：MikroTik 更便宜
A24: 工业 Bypass | B24: LT-IS63xx-FBP 系列 | C24: 光纤 Bypass 管理型 | D24: 960 | E24: =IF(D24="","",ROUND(D24/参数!$B$2,0)) | F24: =IF(D24="","",ROUND(D24/参数!$B$2*(1+参数!$B$3),0)) | G24: 960–1640
A25: 工业 L3 | B25: LT-IS65xx 系列 | C25: 工业 L3 | D25: 1900 | E25: =IF(D25="","",ROUND(D25/参数!$B$2,0)) | F25: =IF(D25="","",ROUND(D25/参数!$B$2*(1+参数!$B$3),0)) | G25: 1900–3100

Sheet 原Excel数据修正
A1: 型号 | B1: 原 Excel 值 | C1: 官网实测值 | D1: 说明
A2: CSS326-24G-2S+RM 芯片 | B2: 98DX3236 | C2: 98DX3216 | D2: 离线库写错
A3: CSS610-8G-2S+IN 芯片 | B3: 98DX3236 / 88E6193X 两行 | C3: 88E6193X | D3: 离线库与在线抓取不一致
A4: CSS610-8G-2S+IN 价格 | B4: $89 / $119 | C4: $119
A5: CRS326-24G-2S+RM 价格 | B5: $219 | C5: $209
A6: CRS328-24P-4S+RM 价格 | B6: $499 / $489 | C6: $489
A7: CRS320-8P-8B-4S+RM 价格 | B7: $299 / $489 | C7: 待核实 | D7: 两行不一致
A8: RB260GSP | B8: 端口写成 260x GbE | C8: 5×GbE + 1×SFP | D8: 正则解析错误行，建议删除
A9: 整体 | B9: 72 行含十余行重复 | C9: 按 product_code 去重，以在线值为准 | D9: 两种 URL slug 抓了两遍
